Traceback (most recent call last):
  File "/home/ariadna/Documentos/TFG/bin/algorithm_v0.3.py", line 41, in main
    data = pd.read_csv(args.input)
           ^^^^^^^^^^^^^^^^^^^^^^^
  File "/home/ariadna/Documentos/TFG/env/lib/python3.12/site-packages/pandas/io/parsers/readers.py", line 1026, in read_csv
    return _read(filepath_or_buffer, kwds)
           ^^^^^^^^^^^^^^^^^^^^^^^^^^^^^^^
  File "/home/ariadna/Documentos/TFG/env/lib/python3.12/site-packages/pandas/io/parsers/readers.py", line 620, in _read
    parser = TextFileReader(filepath_or_buffer, **kwds)
             ^^^^^^^^^^^^^^^^^^^^^^^^^^^^^^^^^^^^^^^^^^
  File "/home/ariadna/Documentos/TFG/env/lib/python3.12/site-packages/pandas/io/parsers/readers.py", line 1620, in __init__
    self._engine = self._make_engine(f, self.engine)
                   ^^^^^^^^^^^^^^^^^^^^^^^^^^^^^^^^^
  File "/home/ariadna/Documentos/TFG/env/lib/python3.12/site-packages/pandas/io/parsers/readers.py", line 1880, in _make_engine
    self.handles = get_handle(
                   ^^^^^^^^^^^
  File "/home/ariadna/Documentos/TFG/env/lib/python3.12/site-packages/pandas/io/common.py", line 873, in get_handle
    handle = open(
             ^^^^^
FileNotFoundError: [Errno 2] No such file or directory: 'case7_erased.csv'

During handling of the above exception, another exception occurred:

Traceback (most recent call last):
  File "/home/ariadna/Documentos/TFG/bin/algorithm_v0.3.py", line 169, in <module>
    main()
  File "/home/ariadna/Documentos/TFG/bin/algorithm_v0.3.py", line 43, in main
    raise FileNotFoundError(f"Input file not found: {args.input}")
FileNotFoundError: Input file not found: case7_erased.csv

real	0m0,870s
user	0m3,246s
sys	0m0,124s
