Traceback (most recent call last):
  File "/home/ariadna/Documentos/TFG/bin/branch_and_bound.py", line 77, in <module>
    df = pd.read_csv(args.input)
         ^^^^^^^^^^^^^^^^^^^^^^^
  File "/home/ariadna/Documentos/TFG/env/lib/python3.12/site-packages/pandas/io/parsers/readers.py", line 1026, in read_csv
    return _read(filepath_or_buffer, kwds)
           ^^^^^^^^^^^^^^^^^^^^^^^^^^^^^^^
  File "/home/ariadna/Documentos/TFG/env/lib/python3.12/site-packages/pandas/io/parsers/readers.py", line 620, in _read
    parser = TextFileReader(filepath_or_buffer, **kwds)
             ^^^^^^^^^^^^^^^^^^^^^^^^^^^^^^^^^^^^^^^^^^
  File "/home/ariadna/Documentos/TFG/env/lib/python3.12/site-packages/pandas/io/parsers/readers.py", line 1620, in __init__
    self._engine = self._make_engine(f, self.engine)
                   ^^^^^^^^^^^^^^^^^^^^^^^^^^^^^^^^^
  File "/home/ariadna/Documentos/TFG/env/lib/python3.12/site-packages/pandas/io/parsers/readers.py", line 1880, in _make_engine
    self.handles = get_handle(
                   ^^^^^^^^^^^
  File "/home/ariadna/Documentos/TFG/env/lib/python3.12/site-packages/pandas/io/common.py", line 873, in get_handle
    handle = open(
             ^^^^^
FileNotFoundError: [Errno 2] No such file or directory: 'case7_erased.csv'

real	0m0,252s
user	0m1,463s
sys	0m0,043s
